<?xml version="1.0" encoding="utf-8"?>
<!-- This URDF was automatically created by SolidWorks to URDF Exporter! Originally created by Stephen Brawner (brawner@gmail.com) 
     Commit Version: 1.6.0-1-g15f4949  Build Version: 1.6.7594.29634
     For more information, please see http://wiki.ros.org/sw_urdf_exporter -->
<robot
  name="kick_ass">
  <material name="rubber">
    <color rgba="0.2 0.2 0.2 1"/>
  </material>
  <material name="red_metal">
    <color rgba="0.8 0.2 0.2 1"/>
  </material>  
  <link
    name="dummy_link">
  </link>
  <joint
    name="dummy_joint" type="fixed">
    <parent
      link="dummy_link"/>
    <child
      link="base_link"/>
  </joint> 
  <link
    name="base_link">
    <inertial>
      <origin
        xyz="-1.04658542068147E-16 2.34969614561294E-18 0.000112931992782061"
        rpy="0 0 0" />
      <mass
        value="17.3033358139167" />
      <inertia
        ixx="0.217206071999271"
        ixy="2.30287082534763E-18"
        ixz="-6.85943635886086E-17"
        iyy="0.465962651746304"
        iyz="-1.94812130552235E-18"
        izz="0.664228867649963" />
    </inertial>
    <visual>
      <origin
        xyz="0 0 0"
        rpy="0 0 0" />
      <geometry>
        <mesh
          filename="/home/jeffin/check_r2/src/kick_ass/meshes/base_link.STL" />
      </geometry>
      <material name="red_metal"/>
    </visual>
    <collision>
      <origin
        xyz="0 0 0"
        rpy="0 0 0" />
      <geometry>
        <mesh
          filename="/home/jeffin/check_r2/src/kick_ass/meshes/base_link.STL" />
      </geometry>
    </collision>
  </link>
  <link
    name="front_right_l">
    <inertial>
      <origin
        xyz="0 0 0"
        rpy="0 0 0" />
      <mass
        value="1.12654353053669" />
      <inertia
        ixx="0.00458630770039492"
        ixy="-5.33132604373309E-19"
        ixz="-3.91815289821087E-05"
        iyy="0.00897972256041491"
        iyz="5.24362894374986E-19"
        izz="0.00463181403006169" />
    </inertial>
    <visual>
      <origin
        xyz="-0.231047754500992 0.234450974563423 2.92985224204485E-17"
        rpy="0 0 0" />
      <geometry>
        <mesh
          filename="/home/jeffin/check_r2/src/kick_ass/meshes/front_right_l.STL" />
      </geometry>
      <material name="rubber"/>
    </visual>
    <collision>
      <origin
        xyz="-0.231047754500992 0.234450974563423 2.92985224204485E-17"
        rpy="0 0 0" />
      <geometry>
        <mesh
          filename="/home/jeffin/check_r2/src/kick_ass/meshes/front_right_l.STL" />
      </geometry>
    </collision>
  </link>
  <joint
    name="front_right_j"
    type="continuous">
    <origin
      xyz="0.231047754500992 -0.234450974563423 -2.92985224204485E-17"
      rpy="0 0 0" />
    <parent
      link="base_link" />
    <child
      link="front_right_l" />
    <axis
      xyz="0 1 0" />
  </joint>
  <link
    name="front_left_l">
    <inertial>
      <origin
        xyz="0 0 0"
        rpy="0 0 0" />
      <mass
        value="1.12654353053669" />
      <inertia
        ixx="0.00459850526638101"
        ixy="2.20168691423562E-19"
        ixz="4.4062206666102E-05"
        iyy="0.0089797225604149"
        iyz="3.59837626294868E-19"
        izz="0.00461961646407558" />
    </inertial>
    <visual>
      <origin
        xyz="-0.231047754500992 -0.234450974563423 -1.04385729653699E-17"
        rpy="0 0 0" />
      <geometry>
        <mesh
          filename="/home/jeffin/check_r2/src/kick_ass/meshes/front_left_l.STL" />
      </geometry>
      <material name="rubber"/>
    </visual>
    <collision>
      <origin
        xyz="-0.231047754500992 -0.234450974563423 -1.04385729653699E-17"
        rpy="0 0 0" />
      <geometry>
        <mesh
          filename="/home/jeffin/check_r2/src/kick_ass/meshes/front_left_l.STL" />
      </geometry>
    </collision>
  </link>
  <joint
    name="front_left_j"
    type="continuous">
    <origin
      xyz="0.231047754500992 0.234450974563423 1.04385729653699E-17"
      rpy="0 0 0" />
    <parent
      link="base_link" />
    <child
      link="front_left_l" />
    <axis
      xyz="0 1 0" />
  </joint>
  <link
    name="back_left_l">
    <inertial>
      <origin
        xyz="0 0 0"
        rpy="0 0 0" />
      <mass
        value="1.12654353053669" />
      <inertia
        ixx="0.004649461662839"
        ixy="-2.26917256793971E-19"
        ixz="2.05103455780415E-05"
        iyy="0.00897972256041491"
        iyz="-3.4866481289621E-19"
        izz="0.00456866006761761" />
    </inertial>
    <visual>
      <origin
        xyz="0.231047754500992 -0.234450974563423 -2.69112687328919E-17"
        rpy="0 0 0" />
      <geometry>
        <mesh
          filename="/home/jeffin/check_r2/src/kick_ass/meshes/back_left_l.STL" />
      </geometry>
      <material name="rubber"/>
    </visual>
    <collision>
      <origin
        xyz="0.231047754500992 -0.234450974563423 -2.69112687328919E-17"
        rpy="0 0 0" />
      <geometry>
        <mesh
          filename="/home/jeffin/check_r2/src/kick_ass/meshes/back_left_l.STL" />
      </geometry>
    </collision>
  </link>
  <joint
    name="back_left_j"
    type="continuous">
    <origin
      xyz="-0.231047754500992 0.234450974563423 2.69112687328919E-17"
      rpy="0 0 0" />
    <parent
      link="base_link" />
    <child
      link="back_left_l" />
    <axis
      xyz="0 1 0" />
  </joint>
  <link
    name="back_right_l">
    <inertial>
      <origin
        xyz="0 0 0"
        rpy="0 0 0" />
      <mass
        value="1.12654353053669" />
      <inertia
        ixx="0.00459954169749984"
        ixy="-1.08468395588852E-21"
        ixz="-4.42976767908718E-05"
        iyy="0.00897972256041491"
        iyz="-6.08958554250286E-19"
        izz="0.00461858003295676" />
    </inertial>
    <visual>
      <origin
        xyz="0.231047754500992 0.234450974563423 -3.57290949123175E-17"
        rpy="0 0 0" />
      <geometry>
        <mesh
          filename="/home/jeffin/check_r2/src/kick_ass/meshes/back_right_l.STL" />
      </geometry>
      <material name="rubber"/>
    </visual>
    <collision>
      <origin
        xyz="0.231047754500992 0.234450974563423 -3.57290949123175E-17"
        rpy="0 0 0" />
      <geometry>
        <mesh
          filename="/home/jeffin/check_r2/src/kick_ass/meshes/back_right_l.STL" />
      </geometry>
    </collision>
  </link>
  <joint
    name="back_right_j"
    type="continuous">
    <origin
      xyz="-0.231047754500992 -0.234450974563423 3.57290949123175E-17"
      rpy="0 0 0" />
    <parent
      link="base_link" />
    <child
      link="back_right_l" />
    <axis
      xyz="0 1 0" />
  </joint>

  <link name='laser_link'>
    <visual>
      <origin xyz="0 0 0" rpy="0 0 0" />
      <geometry>
        <box size="0.02 0.04 0.185" />
      </geometry>
    </visual>
  </link>

  <joint name="laser_link_joint" type="fixed">
    <origin rpy="0 0 0" xyz="0.10 0.0 0.135" />
    <parent link="base_link" />
    <child link="laser_link" />
    <axis xyz="0 0 0" />
  </joint>

  <gazebo reference="laser_link">
    <sensor type="ray" name="head_laser_scanner">
      <pose>0.0 0 0 0 0 0</pose>
      <ray>
        <scan>
          <horizontal>
            <samples>181</samples>
            <resolution>1</resolution>
            <min_angle>-1.57080</min_angle>
            <max_angle>1.57080</max_angle>
          </horizontal>
        </scan>
        <range>
          <min>0.08</min>
          <max>10</max>
          <resolution>0.05</resolution>
        </range>
        <noise>
          <type>gaussian</type>
          <mean>0.0</mean>
          <stddev>0.01</stddev>
        </noise>
      </ray>

      <always_on>1</always_on>
      <update_rate>30</update_rate>
      <visualize>true</visualize>

      <plugin name="laser" filename="libgazebo_ros_ray_sensor.so">
        <ros>
          <namespace>/</namespace>
          <argument>--ros-args --remap ~/out:=scan</argument>
        </ros>
        <output_type>sensor_msgs/LaserScan</output_type>
        <frame_name>laser_link</frame_name>
      </plugin>
    </sensor>
  </gazebo>

	<gazebo reference="base_link">
		<material>Gazebo/Red</material>
	</gazebo>
	<gazebo reference="front_right_l">
		<material>Gazebo/DarkGray</material>
	</gazebo>
	<gazebo reference="front_left_l">
		<material>Gazebo/DarkGray</material>
	</gazebo>
	<gazebo reference="back_right_l">
		<material>Gazebo/DarkGray</material>
	</gazebo>
	<gazebo reference="back_left_l">
		<material>Gazebo/DarkGray</material>
	</gazebo>  

  <gazebo>
    <plugin name="wheel_drive_controller" filename="libgazebo_ros_diff_drive.so">
      
      <!-- wheels -->
      <num_wheel_pairs>2</num_wheel_pairs>
      <left_joint>front_left_j</left_joint>
      <left_joint>back_left_j</left_joint>
      <right_joint>front_right_j</right_joint>
      <right_joint>back_right_j</right_joint>
      
      <!-- kinematics -->
      <wheel_separation>.44</wheel_separation>
      <wheel_diameter>0.243</wheel_diameter>
      <max_wheel_torque>20.0</max_wheel_torque>
      <max_wheel_acceleration>10.0</max_wheel_acceleration>

      <!-- odometry  --> 
      <!-- <odometry_source>world</odometry_source> -->
      <odometry_frame>odom</odometry_frame>
      <robot_base_frame>base_link</robot_base_frame>

      <!-- topic & re remappings -->
      <ros>
        <namespace>/</namespace>
        <argument>--ros-args --remap /cmd_vel:=cmd_vel</argument>
        <argument>--ros-args --remap /odom:=odom</argument>
      </ros>

      <publish_odom>true</publish_odom>
      <publish_odom_tf>true</publish_odom_tf>
      <update_rate>100.0</update_rate>
    </plugin>
  </gazebo>

</robot>

